Global seed set to 77
wandb: Currently logged in as: wowolo (math_zurich). Use `wandb login --relogin` to force relogin
wandb: WARNING Changes to your `wandb` environment variables will be ignored because your `wandb` session has already started. For more information on how to modify your settings with `wandb.init()` arguments, please refer to https://wandb.me/wandb-init.
wandb: Tracking run with wandb version 0.12.21
wandb: Run data is saved locally in /cluster/home/scheins/master_thesis/visualization/wandb/run-20220720_095643-2oyg2lzb
wandb: Run `wandb offline` to turn off syncing.
wandb: Syncing run euler_test2_config0
wandb: ‚≠êÔ∏è View project at https://wandb.ai/math_zurich/visualization
wandb: üöÄ View run at https://wandb.ai/math_zurich/visualization/runs/2oyg2lzb
GPU available: True, used: True
TPU available: False, using: 0 TPU cores
IPU available: False, using: 0 IPUs
HPU available: False, using: 0 HPUs
Global seed set to 77
[34m[1mwandb[0m: Currently logged in as: [33mwowolo[0m ([33mmath_zurich[0m). Use [1m`wandb login --relogin`[0m to force relogin
Global seed set to 77
Initializing distributed: GLOBAL_RANK: 1, MEMBER: 2/8
Global seed set to 77
[34m[1mwandb[0m: Currently logged in as: [33mwowolo[0m ([33mmath_zurich[0m). Use [1m`wandb login --relogin`[0m to force relogin
Global seed set to 77
Initializing distributed: GLOBAL_RANK: 2, MEMBER: 3/8
Global seed set to 77
Global seed set to 77
[34m[1mwandb[0m: Currently logged in as: [33mwowolo[0m ([33mmath_zurich[0m). Use [1m`wandb login --relogin`[0m to force relogin
Global seed set to 77
Initializing distributed: GLOBAL_RANK: 3, MEMBER: 4/8
[34m[1mwandb[0m: Currently logged in as: [33mwowolo[0m ([33mmath_zurich[0m). Use [1m`wandb login --relogin`[0m to force relogin
Global seed set to 77
Initializing distributed: GLOBAL_RANK: 4, MEMBER: 5/8
Global seed set to 77
[34m[1mwandb[0m: Currently logged in as: [33mwowolo[0m ([33mmath_zurich[0m). Use [1m`wandb login --relogin`[0m to force relogin
Global seed set to 77
Initializing distributed: GLOBAL_RANK: 5, MEMBER: 6/8
Global seed set to 77
Initializing distributed: GLOBAL_RANK: 0, MEMBER: 1/8
Global seed set to 77
Global seed set to 77
[34m[1mwandb[0m: Currently logged in as: [33mwowolo[0m ([33mmath_zurich[0m). Use [1m`wandb login --relogin`[0m to force relogin
Global seed set to 77
Initializing distributed: GLOBAL_RANK: 6, MEMBER: 7/8
[34m[1mwandb[0m: Currently logged in as: [33mwowolo[0m ([33mmath_zurich[0m). Use [1m`wandb login --relogin`[0m to force relogin
Global seed set to 77
Initializing distributed: GLOBAL_RANK: 7, MEMBER: 8/8
----------------------------------------------------------------------------------------------------
distributed_backend=nccl
All distributed processes registered. Starting with 8 processes
----------------------------------------------------------------------------------------------------

LOCAL_RANK: 0 - CUDA_VISIBLE_DEVICES: [6,7,0,4,2,1,5,3]
LOCAL_RANK: 1 - CUDA_VISIBLE_DEVICES: [6,7,0,4,2,1,5,3]
LOCAL_RANK: 3 - CUDA_VISIBLE_DEVICES: [6,7,0,4,2,1,5,3]
LOCAL_RANK: 2 - CUDA_VISIBLE_DEVICES: [6,7,0,4,2,1,5,3]
LOCAL_RANK: 4 - CUDA_VISIBLE_DEVICES: [6,7,0,4,2,1,5,3]
LOCAL_RANK: 6 - CUDA_VISIBLE_DEVICES: [6,7,0,4,2,1,5,3]
LOCAL_RANK: 5 - CUDA_VISIBLE_DEVICES: [6,7,0,4,2,1,5,3]
LOCAL_RANK: 7 - CUDA_VISIBLE_DEVICES: [6,7,0,4,2,1,5,3]

  | Name  | Type    | Params
----------------------------------
0 | model | NNModel | 10.5 M
----------------------------------
10.5 M    Trainable params
0         Non-trainable params
10.5 M    Total params
42.178    Total estimated model params size (MB)
/cluster/home/scheins/master_thesis/visualization/visual_env/lib64/python3.9/site-packages/plotly/matplotlylib/renderer.py:611: UserWarning:

I found a path object that I don't think is part of a bar chart. Ignoring.

/cluster/home/scheins/master_thesis/visualization/visual_env/lib64/python3.9/site-packages/pytorch_lightning/trainer/connectors/data_connector.py:240: PossibleUserWarning:

The dataloader, train_dataloader, does not have many workers which may be a bottleneck. Consider increasing the value of the `num_workers` argument` (try 72 which is the number of cpus on this machine) in the `DataLoader` init to improve performance.

/cluster/home/scheins/master_thesis/visualization/visual_env/lib64/python3.9/site-packages/pytorch_lightning/trainer/trainer.py:1933: PossibleUserWarning:

The number of training batches (2) is smaller than the logging interval Trainer(log_every_n_steps=50). Set a lower value for log_every_n_steps if you want to see logs for the training epoch.

wandb: Network error (ReadTimeout), entering retry loop.
wandb: Network error (ReadTimeout), entering retry loop.
Traceback (most recent call last):
  File "/cluster/home/scheins/master_thesis/visualization/visual_env/lib64/python3.9/site-packages/pytorch_lightning/trainer/trainer.py", line 721, in _call_and_handle_interrupt
    return self.strategy.launcher.launch(trainer_fn, *args, trainer=self, **kwargs)
  File "/cluster/home/scheins/master_thesis/visualization/visual_env/lib64/python3.9/site-packages/pytorch_lightning/strategies/launchers/subprocess_script.py", line 93, in launch
    return function(*args, **kwargs)
  File "/cluster/home/scheins/master_thesis/visualization/visual_env/lib64/python3.9/site-packages/pytorch_lightning/trainer/trainer.py", line 811, in _fit_impl
    results = self._run(model, ckpt_path=self.ckpt_path)
  File "/cluster/home/scheins/master_thesis/visualization/visual_env/lib64/python3.9/site-packages/pytorch_lightning/trainer/trainer.py", line 1236, in _run
    results = self._run_stage()
  File "/cluster/home/scheins/master_thesis/visualization/visual_env/lib64/python3.9/site-packages/pytorch_lightning/trainer/trainer.py", line 1323, in _run_stage
    return self._run_train()
  File "/cluster/home/scheins/master_thesis/visualization/visual_env/lib64/python3.9/site-packages/pytorch_lightning/trainer/trainer.py", line 1353, in _run_train
    self.fit_loop.run()
  File "/cluster/home/scheins/master_thesis/visualization/visual_env/lib64/python3.9/site-packages/pytorch_lightning/loops/base.py", line 205, in run
    self.on_advance_end()
  File "/cluster/home/scheins/master_thesis/visualization/visual_env/lib64/python3.9/site-packages/pytorch_lightning/loops/fit_loop.py", line 297, in on_advance_end
    self.trainer._call_callback_hooks("on_train_epoch_end")
  File "/cluster/home/scheins/master_thesis/visualization/visual_env/lib64/python3.9/site-packages/pytorch_lightning/trainer/trainer.py", line 1636, in _call_callback_hooks
    fn(self, self.lightning_module, *args, **kwargs)
  File "/cluster/home/scheins/master_thesis/visualization/visual_env/lib64/python3.9/site-packages/pytorch_lightning/callbacks/model_checkpoint.py", line 308, in on_train_epoch_end
    self._save_topk_checkpoint(trainer, monitor_candidates)
  File "/cluster/home/scheins/master_thesis/visualization/visual_env/lib64/python3.9/site-packages/pytorch_lightning/callbacks/model_checkpoint.py", line 381, in _save_topk_checkpoint
    self._save_none_monitor_checkpoint(trainer, monitor_candidates)
  File "/cluster/home/scheins/master_thesis/visualization/visual_env/lib64/python3.9/site-packages/pytorch_lightning/callbacks/model_checkpoint.py", line 661, in _save_none_monitor_checkpoint
    self._save_checkpoint(trainer, filepath)
  File "/cluster/home/scheins/master_thesis/visualization/visual_env/lib64/python3.9/site-packages/pytorch_lightning/callbacks/model_checkpoint.py", line 384, in _save_checkpoint
    trainer.save_checkpoint(filepath, self.save_weights_only)
  File "/cluster/home/scheins/master_thesis/visualization/visual_env/lib64/python3.9/site-packages/pytorch_lightning/trainer/trainer.py", line 2467, in save_checkpoint
    self._checkpoint_connector.save_checkpoint(filepath, weights_only=weights_only, storage_options=storage_options)
  File "/cluster/home/scheins/master_thesis/visualization/visual_env/lib64/python3.9/site-packages/pytorch_lightning/trainer/connectors/checkpoint_connector.py", line 445, in save_checkpoint
    self.trainer.strategy.save_checkpoint(_checkpoint, filepath, storage_options=storage_options)
  File "/cluster/home/scheins/master_thesis/visualization/visual_env/lib64/python3.9/site-packages/pytorch_lightning/strategies/strategy.py", line 418, in save_checkpoint
    self.checkpoint_io.save_checkpoint(checkpoint, filepath, storage_options=storage_options)
  File "/cluster/home/scheins/master_thesis/visualization/visual_env/lib64/python3.9/site-packages/pytorch_lightning/plugins/io/torch_plugin.py", line 54, in save_checkpoint
    atomic_save(checkpoint, path)
  File "/cluster/home/scheins/master_thesis/visualization/visual_env/lib64/python3.9/site-packages/pytorch_lightning/utilities/cloud_io.py", line 68, in atomic_save
    with fsspec.open(filepath, "wb") as f:
  File "/cluster/home/scheins/master_thesis/visualization/visual_env/lib64/python3.9/site-packages/fsspec/core.py", line 467, in open
    return open_files(
  File "/cluster/home/scheins/master_thesis/visualization/visual_env/lib64/python3.9/site-packages/fsspec/core.py", line 310, in open_files
    [fs.makedirs(parent, exist_ok=True) for parent in parents]
  File "/cluster/home/scheins/master_thesis/visualization/visual_env/lib64/python3.9/site-packages/fsspec/core.py", line 310, in <listcomp>
    [fs.makedirs(parent, exist_ok=True) for parent in parents]
  File "/cluster/home/scheins/master_thesis/visualization/visual_env/lib64/python3.9/site-packages/fsspec/implementations/local.py", line 47, in makedirs
    os.makedirs(path, exist_ok=exist_ok)
  File "/cluster/apps/nss/gcc-8.2.0/python/3.9.9/x86_64/lib64/python3.9/os.py", line 225, in makedirs
    mkdir(name, mode)
FileNotFoundError: [Errno 2] No such file or directory: '/cluster/home/scheins/master_thesis/visualization/visualization/2oyg2lzb/checkpoints'

During handling of the above exception, another exception occurred:

Traceback (most recent call last):
  File "/cluster/home/scheins/master_thesis/visualization/main.py", line 87, in <module>
    main()
  File "/cluster/home/scheins/master_thesis/visualization/main.py", line 82, in main
    manager.run(experimentbatch_name)
  File "/cluster/home/scheins/master_thesis/visualization/experiments/compositeSine/manager.py", line 90, in run
    *data.create_data('train').values(),
  File "/cluster/home/scheins/master_thesis/visualization/core_code/lightning_model.py", line 108, in fit
    trainer.fit(self, data_module)
  File "/cluster/home/scheins/master_thesis/visualization/visual_env/lib64/python3.9/site-packages/pytorch_lightning/trainer/trainer.py", line 770, in fit
    self._call_and_handle_interrupt(
  File "/cluster/home/scheins/master_thesis/visualization/visual_env/lib64/python3.9/site-packages/pytorch_lightning/trainer/trainer.py", line 736, in _call_and_handle_interrupt
    self.strategy.reconciliate_processes(traceback.format_exc())
  File "/cluster/home/scheins/master_thesis/visualization/visual_env/lib64/python3.9/site-packages/pytorch_lightning/strategies/ddp.py", line 451, in reconciliate_processes
    raise DeadlockDetectedException(f"DeadLock detected from rank: {self.global_rank} \n {trace}")
pytorch_lightning.utilities.exceptions.DeadlockDetectedException: DeadLock detected from rank: 0 
 Traceback (most recent call last):
  File "/cluster/home/scheins/master_thesis/visualization/visual_env/lib64/python3.9/site-packages/pytorch_lightning/trainer/trainer.py", line 721, in _call_and_handle_interrupt
    return self.strategy.launcher.launch(trainer_fn, *args, trainer=self, **kwargs)
  File "/cluster/home/scheins/master_thesis/visualization/visual_env/lib64/python3.9/site-packages/pytorch_lightning/strategies/launchers/subprocess_script.py", line 93, in launch
    return function(*args, **kwargs)
  File "/cluster/home/scheins/master_thesis/visualization/visual_env/lib64/python3.9/site-packages/pytorch_lightning/trainer/trainer.py", line 811, in _fit_impl
    results = self._run(model, ckpt_path=self.ckpt_path)
  File "/cluster/home/scheins/master_thesis/visualization/visual_env/lib64/python3.9/site-packages/pytorch_lightning/trainer/trainer.py", line 1236, in _run
    results = self._run_stage()
  File "/cluster/home/scheins/master_thesis/visualization/visual_env/lib64/python3.9/site-packages/pytorch_lightning/trainer/trainer.py", line 1323, in _run_stage
    return self._run_train()
  File "/cluster/home/scheins/master_thesis/visualization/visual_env/lib64/python3.9/site-packages/pytorch_lightning/trainer/trainer.py", line 1353, in _run_train
    self.fit_loop.run()
  File "/cluster/home/scheins/master_thesis/visualization/visual_env/lib64/python3.9/site-packages/pytorch_lightning/loops/base.py", line 205, in run
    self.on_advance_end()
  File "/cluster/home/scheins/master_thesis/visualization/visual_env/lib64/python3.9/site-packages/pytorch_lightning/loops/fit_loop.py", line 297, in on_advance_end
    self.trainer._call_callback_hooks("on_train_epoch_end")
  File "/cluster/home/scheins/master_thesis/visualization/visual_env/lib64/python3.9/site-packages/pytorch_lightning/trainer/trainer.py", line 1636, in _call_callback_hooks
    fn(self, self.lightning_module, *args, **kwargs)
  File "/cluster/home/scheins/master_thesis/visualization/visual_env/lib64/python3.9/site-packages/pytorch_lightning/callbacks/model_checkpoint.py", line 308, in on_train_epoch_end
    self._save_topk_checkpoint(trainer, monitor_candidates)
  File "/cluster/home/scheins/master_thesis/visualization/visual_env/lib64/python3.9/site-packages/pytorch_lightning/callbacks/model_checkpoint.py", line 381, in _save_topk_checkpoint
    self._save_none_monitor_checkpoint(trainer, monitor_candidates)
  File "/cluster/home/scheins/master_thesis/visualization/visual_env/lib64/python3.9/site-packages/pytorch_lightning/callbacks/model_checkpoint.py", line 661, in _save_none_monitor_checkpoint
    self._save_checkpoint(trainer, filepath)
  File "/cluster/home/scheins/master_thesis/visualization/visual_env/lib64/python3.9/site-packages/pytorch_lightning/callbacks/model_checkpoint.py", line 384, in _save_checkpoint
    trainer.save_checkpoint(filepath, self.save_weights_only)
  File "/cluster/home/scheins/master_thesis/visualization/visual_env/lib64/python3.9/site-packages/pytorch_lightning/trainer/trainer.py", line 2467, in save_checkpoint
    self._checkpoint_connector.save_checkpoint(filepath, weights_only=weights_only, storage_options=storage_options)
  File "/cluster/home/scheins/master_thesis/visualization/visual_env/lib64/python3.9/site-packages/pytorch_lightning/trainer/connectors/checkpoint_connector.py", line 445, in save_checkpoint
    self.trainer.strategy.save_checkpoint(_checkpoint, filepath, storage_options=storage_options)
  File "/cluster/home/scheins/master_thesis/visualization/visual_env/lib64/python3.9/site-packages/pytorch_lightning/strategies/strategy.py", line 418, in save_checkpoint
    self.checkpoint_io.save_checkpoint(checkpoint, filepath, storage_options=storage_options)
  File "/cluster/home/scheins/master_thesis/visualization/visual_env/lib64/python3.9/site-packages/pytorch_lightning/plugins/io/torch_plugin.py", line 54, in save_checkpoint
    atomic_save(checkpoint, path)
  File "/cluster/home/scheins/master_thesis/visualization/visual_env/lib64/python3.9/site-packages/pytorch_lightning/utilities/cloud_io.py", line 68, in atomic_save
    with fsspec.open(filepath, "wb") as f:
  File "/cluster/home/scheins/master_thesis/visualization/visual_env/lib64/python3.9/site-packages/fsspec/core.py", line 467, in open
    return open_files(
  File "/cluster/home/scheins/master_thesis/visualization/visual_env/lib64/python3.9/site-packages/fsspec/core.py", line 310, in open_files
    [fs.makedirs(parent, exist_ok=True) for parent in parents]
  File "/cluster/home/scheins/master_thesis/visualization/visual_env/lib64/python3.9/site-packages/fsspec/core.py", line 310, in <listcomp>
    [fs.makedirs(parent, exist_ok=True) for parent in parents]
  File "/cluster/home/scheins/master_thesis/visualization/visual_env/lib64/python3.9/site-packages/fsspec/implementations/local.py", line 47, in makedirs
    os.makedirs(path, exist_ok=exist_ok)
  File "/cluster/apps/nss/gcc-8.2.0/python/3.9.9/x86_64/lib64/python3.9/os.py", line 225, in makedirs
    mkdir(name, mode)
FileNotFoundError: [Errno 2] No such file or directory: '/cluster/home/scheins/master_thesis/visualization/visualization/2oyg2lzb/checkpoints'

--- Logging error ---
Traceback (most recent call last):
  File "/cluster/apps/nss/gcc-8.2.0/python/3.9.9/x86_64/lib64/python3.9/logging/__init__.py", line 1087, in emit
    self.flush()
  File "/cluster/apps/nss/gcc-8.2.0/python/3.9.9/x86_64/lib64/python3.9/logging/__init__.py", line 1067, in flush
    self.stream.flush()
OSError: [Errno 116] Stale file handle
Call stack:
  File "/cluster/home/scheins/master_thesis/visualization/visual_env/lib64/python3.9/site-packages/wandb/sdk/wandb_run.py", line 1900, in <lambda>
    atexit.register(lambda: self._atexit_cleanup())
  File "/cluster/home/scheins/master_thesis/visualization/visual_env/lib64/python3.9/site-packages/wandb/sdk/wandb_run.py", line 1862, in _atexit_cleanup
    logger.info(f"got exitcode: {exit_code}")
Message: 'got exitcode: 1'
Arguments: ()
--- Logging error ---
--- Logging error ---
Traceback (most recent call last):
  File "/cluster/apps/nss/gcc-8.2.0/python/3.9.9/x86_64/lib64/python3.9/logging/__init__.py", line 1087, in emit
    self.flush()
  File "/cluster/apps/nss/gcc-8.2.0/python/3.9.9/x86_64/lib64/python3.9/logging/__init__.py", line 1067, in flush
    self.stream.flush()
OSError: [Errno 116] Stale file handle
Call stack:
Traceback (most recent call last):
  File "/cluster/apps/nss/gcc-8.2.0/python/3.9.9/x86_64/lib64/python3.9/logging/__init__.py", line 1087, in emit
    self.flush()
  File "/cluster/apps/nss/gcc-8.2.0/python/3.9.9/x86_64/lib64/python3.9/logging/__init__.py", line 1067, in flush
    self.stream.flush()
OSError: [Errno 116] Stale file handle
Call stack:
  File "/cluster/home/scheins/master_thesis/visualization/visual_env/lib64/python3.9/site-packages/wandb/sdk/wandb_run.py", line 1900, in <lambda>
    atexit.register(lambda: self._atexit_cleanup())
  File "/cluster/home/scheins/master_thesis/visualization/visual_env/lib64/python3.9/site-packages/wandb/sdk/wandb_run.py", line 1871, in _atexit_cleanup
    self._on_finish()
  File "/cluster/home/scheins/master_thesis/visualization/visual_env/lib64/python3.9/site-packages/wandb/sdk/wandb_run.py", line 1972, in _on_finish
    self._console_stop()  # TODO: there's a race here with jupyter console logging
  File "/cluster/home/scheins/master_thesis/visualization/visual_env/lib64/python3.9/site-packages/wandb/sdk/wandb_run.py", line 1911, in _console_stop
    self._restore()
  File "/cluster/home/scheins/master_thesis/visualization/visual_env/lib64/python3.9/site-packages/wandb/sdk/wandb_run.py", line 1834, in _restore
    logger.info("restore")
Message: 'restore'
Arguments: ()
  File "/cluster/apps/nss/gcc-8.2.0/python/3.9.9/x86_64/lib64/python3.9/threading.py", line 930, in _bootstrap
    self._bootstrap_inner()
  File "/cluster/apps/nss/gcc-8.2.0/python/3.9.9/x86_64/lib64/python3.9/threading.py", line 973, in _bootstrap_inner
    self.run()
  File "/cluster/home/scheins/master_thesis/visualization/visual_env/lib64/python3.9/site-packages/wandb/sdk/internal/internal_util.py", line 51, in run
    self._run()
  File "/cluster/home/scheins/master_thesis/visualization/visual_env/lib64/python3.9/site-packages/wandb/sdk/internal/internal_util.py", line 102, in _run
    self._process(record)
  File "/cluster/home/scheins/master_thesis/visualization/visual_env/lib64/python3.9/site-packages/wandb/sdk/internal/internal.py", line 310, in _process
    self._sm.send(record)
  File "/cluster/home/scheins/master_thesis/visualization/visual_env/lib64/python3.9/site-packages/wandb/sdk/internal/sender.py", line 236, in send
    logger.debug(f"send: {record_type}")
Message: 'send: telemetry'
Arguments: ()
--- Logging error ---
Traceback (most recent call last):
  File "/cluster/apps/nss/gcc-8.2.0/python/3.9.9/x86_64/lib64/python3.9/logging/__init__.py", line 1087, in emit
    self.flush()
  File "/cluster/apps/nss/gcc-8.2.0/python/3.9.9/x86_64/lib64/python3.9/logging/__init__.py", line 1067, in flush
    self.stream.flush()
OSError: [Errno 116] Stale file handle
Call stack:
  File "/cluster/apps/nss/gcc-8.2.0/python/3.9.9/x86_64/lib64/python3.9/threading.py", line 930, in _bootstrap
    self._bootstrap_inner()
  File "/cluster/apps/nss/gcc-8.2.0/python/3.9.9/x86_64/lib64/python3.9/threading.py", line 973, in _bootstrap_inner
    self.run()
  File "/cluster/home/scheins/master_thesis/visualization/visual_env/lib64/python3.9/site-packages/wandb/sdk/internal/internal_util.py", line 51, in run
    self._run()
  File "/cluster/home/scheins/master_thesis/visualization/visual_env/lib64/python3.9/site-packages/wandb/sdk/internal/internal_util.py", line 103, in _run
    self._finish()
  File "/cluster/home/scheins/master_thesis/visualization/visual_env/lib64/python3.9/site-packages/wandb/sdk/internal/internal.py", line 268, in _finish
    self._hm.finish()
  File "/cluster/home/scheins/master_thesis/visualization/visual_env/lib64/python3.9/site-packages/wandb/sdk/internal/handler.py", line 806, in finish
    logger.info("shutting down handler")
Message: 'shutting down handler'
Arguments: ()
--- Logging error ---
Traceback (most recent call last):
  File "/cluster/apps/nss/gcc-8.2.0/python/3.9.9/x86_64/lib64/python3.9/logging/__init__.py", line 1087, in emit
    self.flush()
  File "/cluster/apps/nss/gcc-8.2.0/python/3.9.9/x86_64/lib64/python3.9/logging/__init__.py", line 1067, in flush
    self.stream.flush()
OSError: [Errno 116] Stale file handle
Call stack:
  File "/cluster/apps/nss/gcc-8.2.0/python/3.9.9/x86_64/lib64/python3.9/threading.py", line 930, in _bootstrap
    self._bootstrap_inner()
  File "/cluster/apps/nss/gcc-8.2.0/python/3.9.9/x86_64/lib64/python3.9/threading.py", line 973, in _bootstrap_inner
    self.run()
  File "/cluster/home/scheins/master_thesis/visualization/visual_env/lib64/python3.9/site-packages/wandb/sdk/internal/internal_util.py", line 51, in run
    self._run()
  File "/cluster/home/scheins/master_thesis/visualization/visual_env/lib64/python3.9/site-packages/wandb/sdk/internal/internal_util.py", line 103, in _run
    self._finish()
  File "/cluster/home/scheins/master_thesis/visualization/visual_env/lib64/python3.9/site-packages/wandb/sdk/internal/internal.py", line 313, in _finish
    self._sm.finish()
  File "/cluster/home/scheins/master_thesis/visualization/visual_env/lib64/python3.9/site-packages/wandb/sdk/internal/sender.py", line 1114, in finish
    logger.info("shutting down sender")
Message: 'shutting down sender'
Arguments: ()
--- Logging error ---
Traceback (most recent call last):
  File "/cluster/apps/nss/gcc-8.2.0/python/3.9.9/x86_64/lib64/python3.9/logging/__init__.py", line 1087, in emit
    self.flush()
  File "/cluster/apps/nss/gcc-8.2.0/python/3.9.9/x86_64/lib64/python3.9/logging/__init__.py", line 1067, in flush
    self.stream.flush()
OSError: [Errno 116] Stale file handle
Call stack:
  File "/cluster/apps/nss/gcc-8.2.0/python/3.9.9/x86_64/lib64/python3.9/threading.py", line 930, in _bootstrap
    self._bootstrap_inner()
  File "/cluster/apps/nss/gcc-8.2.0/python/3.9.9/x86_64/lib64/python3.9/threading.py", line 973, in _bootstrap_inner
    self.run()
  File "/cluster/home/scheins/master_thesis/visualization/visual_env/lib64/python3.9/site-packages/wandb/sdk/internal/internal_util.py", line 51, in run
    self._run()
  File "/cluster/home/scheins/master_thesis/visualization/visual_env/lib64/python3.9/site-packages/wandb/sdk/internal/internal_util.py", line 103, in _run
    self._finish()
  File "/cluster/home/scheins/master_thesis/visualization/visual_env/lib64/python3.9/site-packages/wandb/sdk/internal/internal.py", line 313, in _finish
    self._sm.finish()
  File "/cluster/home/scheins/master_thesis/visualization/visual_env/lib64/python3.9/site-packages/wandb/sdk/internal/sender.py", line 1118, in finish
    self._dir_watcher.finish()
  File "/cluster/home/scheins/master_thesis/visualization/visual_env/lib64/python3.9/site-packages/wandb/filesync/dir_watcher.py", line 353, in finish
    logger.info("shutting down directory watcher")
Message: 'shutting down directory watcher'
Arguments: ()
--- Logging error ---
Traceback (most recent call last):
  File "/cluster/apps/nss/gcc-8.2.0/python/3.9.9/x86_64/lib64/python3.9/logging/__init__.py", line 1087, in emit
    self.flush()
  File "/cluster/apps/nss/gcc-8.2.0/python/3.9.9/x86_64/lib64/python3.9/logging/__init__.py", line 1067, in flush
    self.stream.flush()
OSError: [Errno 116] Stale file handle
Call stack:
  File "/cluster/apps/nss/gcc-8.2.0/python/3.9.9/x86_64/lib64/python3.9/threading.py", line 930, in _bootstrap
    self._bootstrap_inner()
  File "/cluster/apps/nss/gcc-8.2.0/python/3.9.9/x86_64/lib64/python3.9/threading.py", line 973, in _bootstrap_inner
    self.run()
  File "/cluster/home/scheins/master_thesis/visualization/visual_env/lib64/python3.9/site-packages/wandb/sdk/internal/internal_util.py", line 51, in run
    self._run()
  File "/cluster/home/scheins/master_thesis/visualization/visual_env/lib64/python3.9/site-packages/wandb/sdk/internal/internal_util.py", line 103, in _run
    self._finish()
  File "/cluster/home/scheins/master_thesis/visualization/visual_env/lib64/python3.9/site-packages/wandb/sdk/internal/internal.py", line 313, in _finish
    self._sm.finish()
  File "/cluster/home/scheins/master_thesis/visualization/visual_env/lib64/python3.9/site-packages/wandb/sdk/internal/sender.py", line 1118, in finish
    self._dir_watcher.finish()
  File "/cluster/home/scheins/master_thesis/visualization/visual_env/lib64/python3.9/site-packages/wandb/filesync/dir_watcher.py", line 367, in finish
    self._file_observer.dispatch_events(
  File "/cluster/home/scheins/master_thesis/visualization/visual_env/lib64/python3.9/site-packages/wandb/vendor/watchdog/observers/api.py", line 368, in dispatch_events
    handler.dispatch(event)
  File "/cluster/home/scheins/master_thesis/visualization/visual_env/lib64/python3.9/site-packages/wandb/vendor/watchdog/events.py", line 454, in dispatch
    _method_map[event_type](event)
  File "/cluster/home/scheins/master_thesis/visualization/visual_env/lib64/python3.9/site-packages/wandb/filesync/dir_watcher.py", line 286, in _on_file_modified
    logger.info(f"file/dir modified: { event.src_path}")
Message: 'file/dir modified: /cluster/home/scheins/master_thesis/visualization/wandb/run-20220720_095643-2oyg2lzb/files/config.yaml'
Arguments: ()
--- Logging error ---
Traceback (most recent call last):
  File "/cluster/apps/nss/gcc-8.2.0/python/3.9.9/x86_64/lib64/python3.9/logging/__init__.py", line 1087, in emit
    self.flush()
  File "/cluster/apps/nss/gcc-8.2.0/python/3.9.9/x86_64/lib64/python3.9/logging/__init__.py", line 1067, in flush
    self.stream.flush()
OSError: [Errno 116] Stale file handle
Call stack:
  File "/cluster/apps/nss/gcc-8.2.0/python/3.9.9/x86_64/lib64/python3.9/threading.py", line 930, in _bootstrap
    self._bootstrap_inner()
  File "/cluster/apps/nss/gcc-8.2.0/python/3.9.9/x86_64/lib64/python3.9/threading.py", line 973, in _bootstrap_inner
    self.run()
  File "/cluster/home/scheins/master_thesis/visualization/visual_env/lib64/python3.9/site-packages/wandb/sdk/internal/internal_util.py", line 51, in run
    self._run()
  File "/cluster/home/scheins/master_thesis/visualization/visual_env/lib64/python3.9/site-packages/wandb/sdk/internal/internal_util.py", line 103, in _run
    self._finish()
  File "/cluster/home/scheins/master_thesis/visualization/visual_env/lib64/python3.9/site-packages/wandb/sdk/internal/internal.py", line 313, in _finish
    self._sm.finish()
  File "/cluster/home/scheins/master_thesis/visualization/visual_env/lib64/python3.9/site-packages/wandb/sdk/internal/sender.py", line 1118, in finish
    self._dir_watcher.finish()
  File "/cluster/home/scheins/master_thesis/visualization/visual_env/lib64/python3.9/site-packages/wandb/filesync/dir_watcher.py", line 367, in finish
    self._file_observer.dispatch_events(
  File "/cluster/home/scheins/master_thesis/visualization/visual_env/lib64/python3.9/site-packages/wandb/vendor/watchdog/observers/api.py", line 368, in dispatch_events
    handler.dispatch(event)
  File "/cluster/home/scheins/master_thesis/visualization/visual_env/lib64/python3.9/site-packages/wandb/vendor/watchdog/events.py", line 454, in dispatch
    _method_map[event_type](event)
  File "/cluster/home/scheins/master_thesis/visualization/visual_env/lib64/python3.9/site-packages/wandb/filesync/dir_watcher.py", line 294, in _on_file_moved
    logger.info(f"file/dir moved: {event.src_path} -> {event.dest_path}")
Message: 'file/dir moved: /cluster/home/scheins/master_thesis/visualization/wandb/run-20220720_095643-2oyg2lzb/files/config.yaml -> /cluster/home/scheins/master_thesis/visualization/wandb/run-20220720_095643-2oyg2lzb/files/wandb-summary.json'
Arguments: ()
--- Logging error ---
Traceback (most recent call last):
  File "/cluster/apps/nss/gcc-8.2.0/python/3.9.9/x86_64/lib64/python3.9/logging/__init__.py", line 1087, in emit
    self.flush()
  File "/cluster/apps/nss/gcc-8.2.0/python/3.9.9/x86_64/lib64/python3.9/logging/__init__.py", line 1067, in flush
    self.stream.flush()
OSError: [Errno 116] Stale file handle
Call stack:
  File "/cluster/apps/nss/gcc-8.2.0/python/3.9.9/x86_64/lib64/python3.9/threading.py", line 930, in _bootstrap
    self._bootstrap_inner()
  File "/cluster/apps/nss/gcc-8.2.0/python/3.9.9/x86_64/lib64/python3.9/threading.py", line 973, in _bootstrap_inner
    self.run()
  File "/cluster/home/scheins/master_thesis/visualization/visual_env/lib64/python3.9/site-packages/wandb/sdk/internal/internal_util.py", line 51, in run
    self._run()
  File "/cluster/home/scheins/master_thesis/visualization/visual_env/lib64/python3.9/site-packages/wandb/sdk/internal/internal_util.py", line 103, in _run
    self._finish()
  File "/cluster/home/scheins/master_thesis/visualization/visual_env/lib64/python3.9/site-packages/wandb/sdk/internal/internal.py", line 313, in _finish
    self._sm.finish()
  File "/cluster/home/scheins/master_thesis/visualization/visual_env/lib64/python3.9/site-packages/wandb/sdk/internal/sender.py", line 1118, in finish
    self._dir_watcher.finish()
  File "/cluster/home/scheins/master_thesis/visualization/visual_env/lib64/python3.9/site-packages/wandb/filesync/dir_watcher.py", line 383, in finish
    logger.info("scan: %s", self._dir)
Message: 'scan: %s'
Arguments: ('/cluster/home/scheins/master_thesis/visualization/wandb/run-20220720_095643-2oyg2lzb/files',)
--- Logging error ---
Traceback (most recent call last):
  File "/cluster/apps/nss/gcc-8.2.0/python/3.9.9/x86_64/lib64/python3.9/logging/__init__.py", line 1087, in emit
    self.flush()
  File "/cluster/apps/nss/gcc-8.2.0/python/3.9.9/x86_64/lib64/python3.9/logging/__init__.py", line 1067, in flush
    self.stream.flush()
OSError: [Errno 116] Stale file handle
Call stack:
  File "/cluster/apps/nss/gcc-8.2.0/python/3.9.9/x86_64/lib64/python3.9/threading.py", line 930, in _bootstrap
    self._bootstrap_inner()
  File "/cluster/apps/nss/gcc-8.2.0/python/3.9.9/x86_64/lib64/python3.9/threading.py", line 973, in _bootstrap_inner
    self.run()
  File "/cluster/home/scheins/master_thesis/visualization/visual_env/lib64/python3.9/site-packages/wandb/sdk/internal/internal_util.py", line 51, in run
    self._run()
  File "/cluster/home/scheins/master_thesis/visualization/visual_env/lib64/python3.9/site-packages/wandb/sdk/internal/internal_util.py", line 103, in _run
    self._finish()
  File "/cluster/home/scheins/master_thesis/visualization/visual_env/lib64/python3.9/site-packages/wandb/sdk/internal/internal.py", line 313, in _finish
    self._sm.finish()
  File "/cluster/home/scheins/master_thesis/visualization/visual_env/lib64/python3.9/site-packages/wandb/sdk/internal/sender.py", line 1118, in finish
    self._dir_watcher.finish()
  File "/cluster/home/scheins/master_thesis/visualization/visual_env/lib64/python3.9/site-packages/wandb/filesync/dir_watcher.py", line 397, in finish
    logger.info("scan save: %s %s", file_path, save_name)
Message: 'scan save: %s %s'
Arguments: ('/cluster/home/scheins/master_thesis/visualization/wandb/run-20220720_095643-2oyg2lzb/files/wandb-summary.json', 'wandb-summary.json')
--- Logging error ---
Traceback (most recent call last):
  File "/cluster/apps/nss/gcc-8.2.0/python/3.9.9/x86_64/lib64/python3.9/logging/__init__.py", line 1087, in emit
    self.flush()
  File "/cluster/apps/nss/gcc-8.2.0/python/3.9.9/x86_64/lib64/python3.9/logging/__init__.py", line 1067, in flush
    self.stream.flush()
OSError: [Errno 116] Stale file handle
Call stack:
  File "/cluster/apps/nss/gcc-8.2.0/python/3.9.9/x86_64/lib64/python3.9/threading.py", line 930, in _bootstrap
    self._bootstrap_inner()
  File "/cluster/apps/nss/gcc-8.2.0/python/3.9.9/x86_64/lib64/python3.9/threading.py", line 973, in _bootstrap_inner
    self.run()
  File "/cluster/home/scheins/master_thesis/visualization/visual_env/lib64/python3.9/site-packages/wandb/sdk/internal/internal_util.py", line 51, in run
    self._run()
  File "/cluster/home/scheins/master_thesis/visualization/visual_env/lib64/python3.9/site-packages/wandb/sdk/internal/internal_util.py", line 103, in _run
    self._finish()
  File "/cluster/home/scheins/master_thesis/visualization/visual_env/lib64/python3.9/site-packages/wandb/sdk/internal/internal.py", line 313, in _finish
    self._sm.finish()
  File "/cluster/home/scheins/master_thesis/visualization/visual_env/lib64/python3.9/site-packages/wandb/sdk/internal/sender.py", line 1121, in finish
    self._pusher.finish()
  File "/cluster/home/scheins/master_thesis/visualization/visual_env/lib64/python3.9/site-packages/wandb/sdk/internal/file_pusher.py", line 171, in finish
    logger.info("shutting down file pusher")
Message: 'shutting down file pusher'
Arguments: ()
--- Logging error ---
Traceback (most recent call last):
  File "/cluster/apps/nss/gcc-8.2.0/python/3.9.9/x86_64/lib64/python3.9/logging/__init__.py", line 1087, in emit
    self.flush()
  File "/cluster/apps/nss/gcc-8.2.0/python/3.9.9/x86_64/lib64/python3.9/logging/__init__.py", line 1067, in flush
    self.stream.flush()
OSError: [Errno 116] Stale file handle
Call stack:
  File "/cluster/apps/nss/gcc-8.2.0/python/3.9.9/x86_64/lib64/python3.9/threading.py", line 930, in _bootstrap
    self._bootstrap_inner()
  File "/cluster/apps/nss/gcc-8.2.0/python/3.9.9/x86_64/lib64/python3.9/threading.py", line 973, in _bootstrap_inner
    self.run()
  File "/cluster/home/scheins/master_thesis/visualization/visual_env/lib64/python3.9/site-packages/wandb/sdk/internal/internal_util.py", line 51, in run
    self._run()
  File "/cluster/home/scheins/master_thesis/visualization/visual_env/lib64/python3.9/site-packages/wandb/sdk/internal/internal_util.py", line 103, in _run
    self._finish()
  File "/cluster/home/scheins/master_thesis/visualization/visual_env/lib64/python3.9/site-packages/wandb/sdk/internal/internal.py", line 313, in _finish
    self._sm.finish()
  File "/cluster/home/scheins/master_thesis/visualization/visual_env/lib64/python3.9/site-packages/wandb/sdk/internal/sender.py", line 1122, in finish
    self._pusher.join()
  File "/cluster/home/scheins/master_thesis/visualization/visual_env/lib64/python3.9/site-packages/wandb/sdk/internal/file_pusher.py", line 176, in join
    logger.info("waiting for file pusher")
Message: 'waiting for file pusher'
Arguments: ()
--- Logging error ---
Traceback (most recent call last):
  File "/cluster/home/scheins/master_thesis/visualization/visual_env/lib64/python3.9/site-packages/wandb/sdk/wandb_run.py", line 1871, in _atexit_cleanup
    self._on_finish()
  File "/cluster/home/scheins/master_thesis/visualization/visual_env/lib64/python3.9/site-packages/wandb/sdk/wandb_run.py", line 1972, in _on_finish
    self._console_stop()  # TODO: there's a race here with jupyter console logging
  File "/cluster/home/scheins/master_thesis/visualization/visual_env/lib64/python3.9/site-packages/wandb/sdk/wandb_run.py", line 1913, in _console_stop
    self._output_writer.close()
  File "/cluster/home/scheins/master_thesis/visualization/visual_env/lib64/python3.9/site-packages/wandb/sdk/lib/filesystem.py", line 69, in close
    super().close()
  File "/cluster/home/scheins/master_thesis/visualization/visual_env/lib64/python3.9/site-packages/wandb/sdk/lib/filesystem.py", line 38, in close
    self.f.close()
OSError: [Errno 116] Stale file handle

During handling of the above exception, another exception occurred:

Traceback (most recent call last):
  File "/cluster/apps/nss/gcc-8.2.0/python/3.9.9/x86_64/lib64/python3.9/logging/__init__.py", line 1087, in emit
    self.flush()
  File "/cluster/apps/nss/gcc-8.2.0/python/3.9.9/x86_64/lib64/python3.9/logging/__init__.py", line 1067, in flush
    self.stream.flush()
OSError: [Errno 116] Stale file handle
Call stack:
  File "/cluster/home/scheins/master_thesis/visualization/visual_env/lib64/python3.9/site-packages/wandb/sdk/wandb_run.py", line 1900, in <lambda>
    atexit.register(lambda: self._atexit_cleanup())
  File "/cluster/home/scheins/master_thesis/visualization/visual_env/lib64/python3.9/site-packages/wandb/sdk/wandb_run.py", line 1881, in _atexit_cleanup
    self._console_stop()
  File "/cluster/home/scheins/master_thesis/visualization/visual_env/lib64/python3.9/site-packages/wandb/sdk/wandb_run.py", line 1911, in _console_stop
    self._restore()
  File "/cluster/home/scheins/master_thesis/visualization/visual_env/lib64/python3.9/site-packages/wandb/sdk/wandb_run.py", line 1834, in _restore
    logger.info("restore")
Message: 'restore'
Arguments: ()
--- Logging error ---
Traceback (most recent call last):
  File "/cluster/apps/nss/gcc-8.2.0/python/3.9.9/x86_64/lib64/python3.9/logging/__init__.py", line 1087, in emit
    self.flush()
  File "/cluster/apps/nss/gcc-8.2.0/python/3.9.9/x86_64/lib64/python3.9/logging/__init__.py", line 1067, in flush
    self.stream.flush()
OSError: [Errno 116] Stale file handle
Call stack:
  File "/cluster/apps/nss/gcc-8.2.0/python/3.9.9/x86_64/lib64/python3.9/threading.py", line 930, in _bootstrap
    self._bootstrap_inner()
  File "/cluster/apps/nss/gcc-8.2.0/python/3.9.9/x86_64/lib64/python3.9/threading.py", line 973, in _bootstrap_inner
    self.run()
  File "/cluster/home/scheins/master_thesis/visualization/visual_env/lib64/python3.9/site-packages/wandb/filesync/upload_job.py", line 62, in run
    success = self.push()
  File "/cluster/home/scheins/master_thesis/visualization/visual_env/lib64/python3.9/site-packages/wandb/filesync/upload_job.py", line 138, in push
    logger.info("Uploaded file %s", self.save_path)
Message: 'Uploaded file %s'
Arguments: ('/cluster/home/scheins/master_thesis/visualization/wandb/run-20220720_095643-2oyg2lzb/files/wandb-summary.json',)
--- Logging error ---
Traceback (most recent call last):
  File "/cluster/apps/nss/gcc-8.2.0/python/3.9.9/x86_64/lib64/python3.9/logging/__init__.py", line 1087, in emit
    self.flush()
  File "/cluster/apps/nss/gcc-8.2.0/python/3.9.9/x86_64/lib64/python3.9/logging/__init__.py", line 1067, in flush
    self.stream.flush()
OSError: [Errno 116] Stale file handle
Call stack:
  File "<string>", line 1, in <module>
  File "/cluster/apps/nss/gcc-8.2.0/python/3.9.9/x86_64/lib64/python3.9/multiprocessing/spawn.py", line 116, in spawn_main
    exitcode = _main(fd, parent_sentinel)
  File "/cluster/apps/nss/gcc-8.2.0/python/3.9.9/x86_64/lib64/python3.9/multiprocessing/spawn.py", line 129, in _main
    return self._bootstrap(parent_sentinel)
  File "/cluster/apps/nss/gcc-8.2.0/python/3.9.9/x86_64/lib64/python3.9/multiprocessing/process.py", line 315, in _bootstrap
    self.run()
  File "/cluster/apps/nss/gcc-8.2.0/python/3.9.9/x86_64/lib64/python3.9/multiprocessing/process.py", line 108, in run
    self._target(*self._args, **self._kwargs)
  File "/cluster/home/scheins/master_thesis/visualization/visual_env/lib64/python3.9/site-packages/wandb/sdk/internal/internal.py", line 165, in wandb_internal
    logger.error(f"Thread {thread.name}:", exc_info=exc_info)
Message: 'Thread WriterThread:'
Arguments: ()
Thread WriterThread:
Traceback (most recent call last):
  File "/cluster/home/scheins/master_thesis/visualization/visual_env/lib64/python3.9/site-packages/wandb/sdk/internal/internal_util.py", line 51, in run
    self._run()
  File "/cluster/home/scheins/master_thesis/visualization/visual_env/lib64/python3.9/site-packages/wandb/sdk/internal/internal_util.py", line 102, in _run
    self._process(record)
  File "/cluster/home/scheins/master_thesis/visualization/visual_env/lib64/python3.9/site-packages/wandb/sdk/internal/internal.py", line 353, in _process
    self._wm.write(record)
  File "/cluster/home/scheins/master_thesis/visualization/visual_env/lib64/python3.9/site-packages/wandb/sdk/internal/writer.py", line 34, in write
    self._ds.write(record)
  File "/cluster/home/scheins/master_thesis/visualization/visual_env/lib64/python3.9/site-packages/wandb/sdk/internal/datastore.py", line 274, in write
    ret = self._write_data(s)
  File "/cluster/home/scheins/master_thesis/visualization/visual_env/lib64/python3.9/site-packages/wandb/sdk/internal/datastore.py", line 256, in _write_data
    os.fsync(self._fp.fileno())
OSError: [Errno 116] Stale file handle
wandb: ERROR Internal wandb error: file data was not synced
--- Logging error ---
Traceback (most recent call last):
  File "/cluster/apps/nss/gcc-8.2.0/python/3.9.9/x86_64/lib64/python3.9/logging/__init__.py", line 1087, in emit
    self.flush()
  File "/cluster/apps/nss/gcc-8.2.0/python/3.9.9/x86_64/lib64/python3.9/logging/__init__.py", line 1067, in flush
    self.stream.flush()
OSError: [Errno 116] Stale file handle
Call stack:
  File "/cluster/home/scheins/master_thesis/visualization/visual_env/lib64/python3.9/site-packages/wandb/sdk/internal/internal.py", line 80, in handle_exit
    logger.info("Internal process exited")
Message: 'Internal process exited'
Arguments: ()
/cluster/apps/nss/gcc-8.2.0/python/3.9.9/x86_64/lib64/python3.9/multiprocessing/resource_tracker.py:216: UserWarning: resource_tracker: There appear to be 6 leaked semaphore objects to clean up at shutdown
  warnings.warn('resource_tracker: There appear to be %d '
